Workbook

Sheet Summary
B3: Scenario | D3: kwh/kwp | E3: 1st Year Production | F3: Cost | G3: Cost/W | H3: Cost/1st year prodcution | I3: Opsun to KB
B4: =Analysis!H2 -> Mikes results | C4: KB | D4: =Analysis!C22 -> 1014 | E4: =Analysis!C23 -> 1932937.5 | F4: =Analysis!D20 -> 2096875 | G4: =Analysis!C20 -> 1.1 | H4: =Analysis!C25 -> 1.0848126 | I4: =(H5-H4)/H4 -> -0.10369212
C5: Opsun 20 | D5: =Analysis!I22 -> 1337 | E5: =Analysis!I23 -> 2007171.2 | F5: =Analysis!J20 -> 1951625 | G5: =Analysis!I20 -> 1.3 | H5: =Analysis!I25 -> 0.9723261
B6: =Analysis!H27 -> KB with better production | C6: KB | D6: =Analysis!C46 -> 1143 | E6: =Analysis!C47 -> 2178843.8 | F6: =Analysis!D44 -> 2096875 | G6: =Analysis!C44 -> 1.1 | H6: =Analysis!C49 -> 0.9623797 | I6: =(H7-H6)/H6 -> 0.010335215
C7: Opsun 20 | D7: =Analysis!I46 -> 1337 | E7: =Analysis!I47 -> 2007171.2 | F7: =Analysis!J44 -> 1951625 | G7: =Analysis!I44 -> 1.3 | H7: =Analysis!I49 -> 0.9723261
B8: =Analysis!H51 -> Declining inverter ratio | C8: KB | D8: =Analysis!C70 -> 1014 | E8: =Analysis!C71 -> 1932937.5 | F8: =Analysis!D68 -> 2105062.5 | G8: =Analysis!C68 -> 1.1042951 | H8: =Analysis!C73 -> 1.0890484 | I8: =(H9-H8)/H8 -> -0.079346548
C9: Opsun 20 | D9: =Analysis!I70 -> 1337 | E9: =Analysis!I71 -> 2007171.2 | F9: =Analysis!J68 -> 2012462.5 | G9: =Analysis!I68 -> 1.3405246 | H9: =Analysis!I73 -> 1.0026362
B10: =Analysis!H75 -> Cheaper modules | C10: KB | D10: =Analysis!C94 -> 1014 | E10: =Analysis!C95 -> 1932937.5 | F10: =Analysis!D92 -> 1849062.5 | G10: =Analysis!C92 -> 0.97 | H10: =Analysis!C97 -> 0.9566075 | I10: =(H11-H10)/H10 -> -0.085211545
C11: Opsun 20 | D11: =Analysis!I94 -> 1337 | E11: =Analysis!I95 -> 2007171.2 | F11: =Analysis!J92 -> 1756462.5 | G11: =Analysis!I92 -> 1.17 | H11: =Analysis!I97 -> 0.87509349
B12: =Analysis!H99 -> Declining inverter ratio and cheaper panels | C12: KB | D12: =Analysis!C118 -> 1014 | E12: =Analysis!C119 -> 1932937.5 | F12: =Analysis!D116 -> 1857250 | G12: =Analysis!C116 -> 0.97429508 | H12: =Analysis!C121 -> 0.96084328 | I12: =(H13-H12)/H12 -> -0.057699018
C13: Opsun 20 | D13: =Analysis!I118 -> 1337 | E13: =Analysis!I119 -> 2007171.2 | F13: =Analysis!J116 -> 1817300 | G13: =Analysis!I116 -> 1.2105246 | H13: =Analysis!I121 -> 0.90540356
B14: =Analysis!H124 -> Declining inverter ratio and cheaper panels and better production | C14: KB | D14: =Analysis!C143 -> 1143 | E14: =Analysis!C144 -> 2178843.8 | F14: =Analysis!D141 -> 1857250 | G14: =Analysis!C141 -> 0.97429508 | H14: =Analysis!C146 -> 0.85240165 | I14: =(H15-H14)/H14 -> 0.062179509
C15: Opsun 20 | D15: =Analysis!I143 -> 1337 | E15: =Analysis!I144 -> 2007171.2 | F15: =Analysis!J141 -> 1817300 | G15: =Analysis!I141 -> 1.2105246 | H15: =Analysis!I146 -> 0.90540356

Sheet Analysis
H2: Mikes results
B3: Panel Wattage | H3: 625
B4: Rack Supplier | D4: KB | F4: OPSUN | H4: OPSUN | J4: OPSUN | L4: OPSUN
B5: Angle | C5: 10 | E5: 10 | G5: 15 | I5: 20 | K5: 25
B6: Number of Modules | C6: 3050 | E6: 3060 | G6: 2655 | I6: 2402 | K6: 2288
B7: DC capacity (W) | C7: =C6*$H$3 -> 1906250 | E7: =E6*$H$3 -> 1912500 | G7: =G6*$H$3 -> 1659375 | I7: =I6*$H$3 -> 1501250 | K7: =K6*$H$3 -> 1430000
B8: AC/DC ratio | C8: 1.6 | E8: 1.6 | G8: 1.6 | I8: 1.6 | K8: 1.6
B9: AC | C9: =C7/C8 -> 1191406.2 | E9: =E7/E8 -> 1195312.5 | G9: =G7/G8 -> 1037109.4 | I9: =I7/I8 -> 938281.25 | K9: =K7/K8 -> 893750
B10: number of inverters | C10: =C9/155000 -> 7.6864919 | E10: =E9/155000 -> 7.7116935 | G10: =G9/155000 -> 6.6910282 | I10: =I9/155000 -> 6.0534274 | K10: =K9/155000 -> 5.766129
B12: Costs
B13: Modules | C13: 0.3 | D13: =C13*C$7 -> 571875 | E13: 0.3 | F13: =E13*E$7 -> 573750 | G13: 0.3 | H13: =G13*G$7 -> 497812.5 | I13: 0.3 | J13: =I13*I$7 -> 450375 | K13: 0.3 | L13: =K13*K$7 -> 429000
B14: Inverters | C14: 0.13 | D14: =C14*C$7 -> 247812.5 | E14: 0.13 | F14: =E14*E$7 -> 248625 | G14: 0.13 | H14: =G14*G$7 -> 215718.75 | I14: 0.13 | J14: =I14*I$7 -> 195162.5 | K14: 0.13 | L14: =K14*K$7 -> 185900
B15: Racking | C15: 0.19 | D15: =C15*C$7 -> 362187.5 | E15: 0.34 | F15: =E15*E$7 -> 650250 | G15: 0.37 | H15: =G15*G$7 -> 613968.75 | I15: 0.39 | J15: =I15*I$7 -> 585487.5 | K15: 0.47 | L15: =K15*K$7 -> 672100
B16: Ballast | C16: 0.03 | D16: =C16*C$7 -> 57187.5 | E16: 0.02 | F16: =E16*E$7 -> 38250 | G16: 0.02 | H16: =G16*G$7 -> 33187.5 | I16: 0.03 | J16: =I16*I$7 -> 45037.5 | K16: 0.03 | L16: =K16*K$7 -> 42900
B17: Other materials | C17: 0.05 | D17: =C17*C$7 -> 95312.5 | E17: 0.05 | F17: =E17*E$7 -> 95625 | G17: 0.05 | H17: =G17*G$7 -> 82968.75 | I17: 0.05 | J17: =I17*I$7 -> 75062.5 | K17: 0.05 | L17: =K17*K$7 -> 71500
B18: Instalation | C18: 0.4 | D18: =C18*C$7 -> 762500 | E18: 0.4 | F18: =E18*E$7 -> 765000 | G18: 0.4 | H18: =G18*G$7 -> 663750 | I18: 0.4 | J18: =I18*I$7 -> 600500 | K18: 0.4 | L18: =K18*K$7 -> 572000
B20: Cost/W | C20: =SUM(C13:C19) -> 1.1 | D20: =SUM(D13:D19) -> 2096875 | E20: =SUM(E13:E19) -> 1.24 | F20: =SUM(F13:F19) -> 2371500 | G20: =SUM(G13:G19) -> 1.27 | H20: =SUM(H13:H19) -> 2107406.2 | I20: =SUM(I13:I19) -> 1.3 | J20: =SUM(J13:J19) -> 1951625 | ... L20: =SUM(L13:L19) -> 1973400
B22: kWh/kWp | C22: 1014 | E22: 1143 | G22: 1252 | I22: 1337 | K22: 1352
B23: Annual Production | C23: =C7*C22/1000 -> 1932937.5 | E23: =E7*E22/1000 -> 2185987.5 | G23: =G7*G22/1000 -> 2077537.5 | I23: =I7*I22/1000 -> 2007171.2 | K23: =K7*K22/1000 -> 1933360
B25: cost/kwh of first year production | C25: =D20/C23 -> 1.0848126 | E25: =F20/E23 -> 1.0848644 | G25: =H20/G23 -> 1.014377 | I25: =J20/I23 -> 0.9723261 | K25: =L20/K23 -> 1.0207101
B27: Scenario 1 | H27: KB with better production
B29: Angle | C29: 10 | E29: 10 | G29: 15 | I29: 20 | K29: 25
B30: Number of Modules | C30: 3050 | E30: 3060 | G30: 2655 | I30: 2402 | K30: 2288
B31: DC capacity (W) | C31: =C30*$H$3 -> 1906250 | E31: =E30*$H$3 -> 1912500 | G31: =G30*$H$3 -> 1659375 | I31: =I30*$H$3 -> 1501250 | K31: =K30*$H$3 -> 1430000
B32: AC/DC ratio | C32: 1.6 | E32: 1.6 | G32: 1.6 | I32: 1.6 | K32: 1.6
B33: AC | C33: =C31/C32 -> 1191406.2 | E33: =E31/E32 -> 1195312.5 | G33: =G31/G32 -> 1037109.4 | I33: =I31/I32 -> 938281.25 | K33: =K31/K32 -> 893750
B34: number of inverters | C34: =C33/155000 -> 7.6864919 | E34: =E33/155000 -> 7.7116935 | G34: =G33/155000 -> 6.6910282 | I34: =I33/155000 -> 6.0534274 | K34: =K33/155000 -> 5.766129
B36: Costs
B37: Modules | C37: 0.3 | D37: =C37*C$7 -> 571875 | E37: 0.3 | F37: =E37*E$7 -> 573750 | G37: 0.3 | H37: =G37*G$7 -> 497812.5 | I37: 0.3 | J37: =I37*I$7 -> 450375 | K37: 0.3 | L37: =K37*K$7 -> 429000
B38: Inverters | C38: 0.13 | D38: =C38*C$7 -> 247812.5 | E38: 0.13 | F38: =E38*E$7 -> 248625 | G38: 0.13 | H38: =G38*G$7 -> 215718.75 | I38: 0.13 | J38: =I38*I$7 -> 195162.5 | K38: 0.13 | L38: =K38*K$7 -> 185900
B39: Racking | C39: 0.19 | D39: =C39*C$7 -> 362187.5 | E39: 0.34 | F39: =E39*E$7 -> 650250 | G39: 0.37 | H39: =G39*G$7 -> 613968.75 | I39: 0.39 | J39: =I39*I$7 -> 585487.5 | K39: 0.47 | L39: =K39*K$7 -> 672100
B40: Ballast | C40: 0.03 | D40: =C40*C$7 -> 57187.5 | E40: 0.02 | F40: =E40*E$7 -> 38250 | G40: 0.02 | H40: =G40*G$7 -> 33187.5 | I40: 0.03 | J40: =I40*I$7 -> 45037.5 | K40: 0.03 | L40: =K40*K$7 -> 42900
B41: Other materials | C41: 0.05 | D41: =C41*C$7 -> 95312.5 | E41: 0.05 | F41: =E41*E$7 -> 95625 | G41: 0.05 | H41: =G41*G$7 -> 82968.75 | I41: 0.05 | J41: =I41*I$7 -> 75062.5 | K41: 0.05 | L41: =K41*K$7 -> 71500
B42: Instalation | C42: 0.4 | D42: =C42*C$7 -> 762500 | E42: 0.4 | F42: =E42*E$7 -> 765000 | G42: 0.4 | H42: =G42*G$7 -> 663750 | I42: 0.4 | J42: =I42*I$7 -> 600500 | K42: 0.4 | L42: =K42*K$7 -> 572000
B44: Cost/W | C44: =SUM(C37:C43) -> 1.1 | D44: =SUM(D37:D43) -> 2096875 | E44: =SUM(E37:E43) -> 1.24 | F44: =SUM(F37:F43) -> 2371500 | G44: =SUM(G37:G43) -> 1.27 | H44: =SUM(H37:H43) -> 2107406.2 | I44: =SUM(I37:I43) -> 1.3 | J44: =SUM(J37:J43) -> 1951625 | ... L44: =SUM(L37:L43) -> 1973400
B46: kWh/kWp | C46: 1143 | E46: 1143 | G46: 1252 | I46: 1337 | K46: 1352
B47: Annual Production | C47: =C31*C46/1000 -> 2178843.8 | E47: =E31*E46/1000 -> 2185987.5 | G47: =G31*G46/1000 -> 2077537.5 | I47: =I31*I46/1000 -> 2007171.2 | K47: =K31*K46/1000 -> 1933360
C49: =D44/C47 -> 0.9623797 | E49: =F44/E47 -> 1.0848644 | G49: =H44/G47 -> 1.014377 | I49: =J44/I47 -> 0.9723261 | K49: =L44/K47 -> 1.0207101
B51: Scenario 2 | H51: Declining inverter ratio
B53: Angle | C53: 10 | E53: 10 | G53: 15 | I53: 20 | K53: 25
...
